Workbook

Sheet README
B2: POKEMON TCG INVESTMENT WORKBOOK v2
B3: Built May 11 2026 | 198-card watchlist | Quant scoring | Auto Buy/Sell signals | 90-day price history engine
B5: v2 — WHAT CHANGED FROM v1
B6: • Watchlist: 25 → 198 cards across vintage / modern / sealed / raw grading / Japanese
B7: • NEW Price History sheet: 90 days of seeded prices per card; refresh script appends new rows
B8: • NEW Quant Scoring: Momentum + Value + Scarcity + Liquidity → 0-100 composite + BUY/HOLD/SELL signal
B9: • NEW Weekly Buy List: auto-generated top 10 buys + top 5 sells every refresh
B10: • NEW Hot Singles: momentum leaders sorted by 7-day price change
B11: • Refresh script v2: appends to Price History + recomputes all signals + outputs weekly digest
B13: WHY THE QUANT SCORE WORKS (and why it's not 'AI' but better)
B14: The composite score (0-100) computes from four orthogonal factors every refresh:
B15: Momentum Score (40%) — recent 7D + 30D price change, weighted toward shorter window
... B66: RED fill = SELL signal / position underwater

Sheet Dashboard
B2: PORTFOLIO DASHBOARD
B3: Live KPIs from Inventory + Realized P&L. Allocation shows current $ vs target.
B5: PORTFOLIO KPIs | F5: ALLOCATION SNAPSHOT
B6: Total Cost Basis | D6: =SUM(Inventory!H5:H58) | F6: Category | G6: Current $ | H6: % of Port
B7: Total Current Value | D7: =SUM(Inventory!K5:K58) | F7: Sealed Modern | G7: =SUMIFS(Inventory!K:K,Inventory!C:C,F7) | H7: =IFERROR(G7/$D$7,0)
B8: Unrealized P&L ($) | D8: =D7-D6 | F8: Modern Chase PSA 10 | G8: =SUMIFS(Inventory!K:K,Inventory!C:C,F8) | H8: =IFERROR(G8/$D$7,0)
B9: Unrealized P&L (%) | D9: =IFERROR(D8/D6,0) | F9: Vintage Graded Singles | G9: =SUMIFS(Inventory!K:K,Inventory!C:C,F9) | H9: =IFERROR(G9/$D$7,0)
B10: Realized P&L (lifetime) | D10: =SUM('Realized P&L'!K5:K45)
B11: Realized + Unrealized | D11: =D8+D10
B12: # Positions Open | D12: =COUNTA(Inventory!B5:B58)
B13: # Cards Sold (lifetime) | D13: =COUNTA('Realized P&L'!B5:B45)
B14: Avg Holding Period (days) | D14: =IFERROR(AVERAGEIFS('Realized P&L'!L5:L45,'Realized P&L'!B5:B45,"<>"),0)
B15: Win Rate % | D15: =IFERROR(COUNTIFS('Realized P&L'!K5:K45,">0",'Realized P&L'!B5:B45,"<>")/COUNTA('Realized P&L'!B5:B45),0)
B17: MARKET PULSE (from Watchlist) | F17: TOP 5 UNREALIZED WINNERS
B18: Watchlist Avg Composite | D18: =AVERAGE(Watchlist!Y5:Y202) | F18: Item | G18: P&L $ | H18: P&L %
B19: # STRONG BUY signals | D19: =COUNTIF(Watchlist!Z5:Z202,"STRONG BUY") | F19: =IFERROR(INDEX(Inventory!D:D,MATCH(LARGE(Inventory!L5:L58,1),Inventory!L:L,0)),"") | G19: =IFERROR(LARGE(Inventory!L5:L58,1),0) | H19: =IFERROR(INDEX(Inventory!M:M,MATCH(LARGE(Inventory!L5:L58,1),Inventory!L:L,0)),0)
B20: # BUY signals | D20: =COUNTIF(Watchlist!Z5:Z202,"BUY") | F20: =IFERROR(INDEX(Inventory!D:D,MATCH(LARGE(Inventory!L5:L58,2),Inventory!L:L,0)),"") | G20: =IFERROR(LARGE(Inventory!L5:L58,2),0) | H20: =IFERROR(INDEX(Inventory!M:M,MATCH(LARGE(Inventory!L5:L58,2),Inventory!L:L,0)),0)
B21: # HOLD signals | D21: =COUNTIF(Watchlist!Z5:Z202,"HOLD") | F21: =IFERROR(INDEX(Inventory!D:D,MATCH(LARGE(Inventory!L5:L58,3),Inventory!L:L,0)),"") | G21: =IFERROR(LARGE(Inventory!L5:L58,3),0) | H21: =IFERROR(INDEX(Inventory!M:M,MATCH(LARGE(Inventory!L5:L58,3),Inventory!L:L,0)),0)
B22: # TRIM signals | D22: =COUNTIF(Watchlist!Z5:Z202,"TRIM") | F22: =IFERROR(INDEX(Inventory!D:D,MATCH(LARGE(Inventory!L5:L58,4),Inventory!L:L,0)),"") | G22: =IFERROR(LARGE(Inventory!L5:L58,4),0) | H22: =IFERROR(INDEX(Inventory!M:M,MATCH(LARGE(Inventory!L5:L58,4),Inventory!L:L,0)),0)
B23: # SELL signals | D23: =COUNTIF(Watchlist!Z5:Z202,"SELL") | F23: =IFERROR(INDEX(Inventory!D:D,MATCH(LARGE(Inventory!L5:L58,5),Inventory!L:L,0)),"") | G23: =IFERROR(LARGE(Inventory!L5:L58,5),0) | H23: =IFERROR(INDEX(Inventory!M:M,MATCH(LARGE(Inventory!L5:L58,5),Inventory!L:L,0)),0)
B24: Avg 30D Trend (watchlist) | D24: =AVERAGE(Watchlist!N5:N202)

Sheet Weekly Buy List
B2: WEEKLY BUY LIST — Auto-Generated
B3: Refreshed: Mon May 11, 2026. Top 10 BUY signals + Top 5 SELL signals. This is your Monday morning shopping list.
B5: TOP 10 BUY SIGNALS
B6: CardID | C6: Card Name | D6: Set | E6: Current Price | F6: Target Buy | G6: Upside to Sell | H6: 30D % | I6: Score | J6: Signal | K6: Why
B7: =IFERROR(INDEX(Watchlist!A:A,MATCH(LARGE(Watchlist!Y5:Y202,1),Watchlist!Y:Y,0)),"") | C7: =IFERROR(INDEX(Watchlist!D:D,MATCH(LARGE(Watchlist!Y5:Y202,1),Watchlist!Y:Y,0)),"") | D7: =IFERROR(INDEX(Watchlist!E:E,MATCH(LARGE(Watchlist!Y5:Y202,1),Watchlist!Y:Y,0)),"") | E7: =IFERROR(INDEX(Watchlist!H:H,MATCH(LARGE(Watchlist!Y5:Y202,1),Watchlist!Y:Y,0)),0) | F7: =IFERROR(INDEX(Watchlist!P:P,MATCH(LARGE(Watchlist!Y5:Y202,1),Watchlist!Y:Y,0)),0) | G7: =IFERROR((INDEX(Watchlist!Q:Q,MATCH(LARGE(Watchlist!Y5:Y202,1),Watchlist!Y:Y,0))/E7)-1,0) | H7: =IFERROR(INDEX(Watchlist!N:N,MATCH(LARGE(Watchlist!Y5:Y202,1),Watchlist!Y:Y,0)),0) | I7: =IFERROR(LARGE(Watchlist!Y5:Y202,1),0) | J7: =IFERROR(INDEX(Watchlist!Z:Z,MATCH(LARGE(Watchlist!Y5:Y202,1),Watchlist!Y:Y,0)),"") | K7: =IFERROR(LEFT(INDEX(Watchlist!AB:AB,MATCH(LARGE(Watchlist!Y5:Y202,1),Watchlist!Y:Y,0)),80),"")
B8: =IFERROR(INDEX(Watchlist!A:A,MATCH(LARGE(Watchlist!Y5:Y202,2),Watchlist!Y:Y,0)),"") | C8: =IFERROR(INDEX(Watchlist!D:D,MATCH(LARGE(Watchlist!Y5:Y202,2),Watchlist!Y:Y,0)),"") | D8: =IFERROR(INDEX(Watchlist!E:E,MATCH(LARGE(Watchlist!Y5:Y202,2),Watchlist!Y:Y,0)),"") | E8: =IFERROR(INDEX(Watchlist!H:H,MATCH(LARGE(Watchlist!Y5:Y202,2),Watchlist!Y:Y,0)),0) | F8: =IFERROR(INDEX(Watchlist!P:P,MATCH(LARGE(Watchlist!Y5:Y202,2),Watchlist!Y:Y,0)),0) | G8: =IFERROR((INDEX(Watchlist!Q:Q,MATCH(LARGE(Watchlist!Y5:Y202,2),Watchlist!Y:Y,0))/E8)-1,0) | H8: =IFERROR(INDEX(Watchlist!N:N,MATCH(LARGE(Watchlist!Y5:Y202,2),Watchlist!Y:Y,0)),0) | I8: =IFERROR(LARGE(Watchlist!Y5:Y202,2),0) | J8: =IFERROR(INDEX(Watchlist!Z:Z,MATCH(LARGE(Watchlist!Y5:Y202,2),Watchlist!Y:Y,0)),"") | K8: =IFERROR(LEFT(INDEX(Watchlist!AB:AB,MATCH(LARGE(Watchlist!Y5:Y202,2),Watchlist!Y:Y,0)),80),"")
B9: =IFERROR(INDEX(Watchlist!A:A,MATCH(LARGE(Watchlist!Y5:Y202,3),Watchlist!Y:Y,0)),"") | C9: =IFERROR(INDEX(Watchlist!D:D,MATCH(LARGE(Watchlist!Y5:Y202,3),Watchlist!Y:Y,0)),"") | D9: =IFERROR(INDEX(Watchlist!E:E,MATCH(LARGE(Watchlist!Y5:Y202,3),Watchlist!Y:Y,0)),"") | E9: =IFERROR(INDEX(Watchlist!H:H,MATCH(LARGE(Watchlist!Y5:Y202,3),Watchlist!Y:Y,0)),0) | F9: =IFERROR(INDEX(Watchlist!P:P,MATCH(LARGE(Watchlist!Y5:Y202,3),Watchlist!Y:Y,0)),0) | G9: =IFERROR((INDEX(Watchlist!Q:Q,MATCH(LARGE(Watchlist!Y5:Y202,3),Watchlist!Y:Y,0))/E9)-1,0) | H9: =IFERROR(INDEX(Watchlist!N:N,MATCH(LARGE(Watchlist!Y5:Y202,3),Watchlist!Y:Y,0)),0) | I9: =IFERROR(LARGE(Watchlist!Y5:Y202,3),0) | J9: =IFERROR(INDEX(Watchlist!Z:Z,MATCH(LARGE(Watchlist!Y5:Y202,3),Watchlist!Y:Y,0)),"") | K9: =IFERROR(LEFT(INDEX(Watchlist!AB:AB,MATCH(LARGE(Watchlist!Y5:Y202,3),Watchlist!Y:Y,0)),80),"")
B10: =IFERROR(INDEX(Watchlist!A:A,MATCH(LARGE(Watchlist!Y5:Y202,4),Watchlist!Y:Y,0)),"") | C10: =IFERROR(INDEX(Watchlist!D:D,MATCH(LARGE(Watchlist!Y5:Y202,4),Watchlist!Y:Y,0)),"") | D10: =IFERROR(INDEX(Watchlist!E:E,MATCH(LARGE(Watchlist!Y5:Y202,4),Watchlist!Y:Y,0)),"") | E10: =IFERROR(INDEX(Watchlist!H:H,MATCH(LARGE(Watchlist!Y5:Y202,4),Watchlist!Y:Y,0)),0) | F10: =IFERROR(INDEX(Watchlist!P:P,MATCH(LARGE(Watchlist!Y5:Y202,4),Watchlist!Y:Y,0)),0) | G10: =IFERROR((INDEX(Watchlist!Q:Q,MATCH(LARGE(Watchlist!Y5:Y202,4),Watchlist!Y:Y,0))/E10)-1,0) | H10: =IFERROR(INDEX(Watchlist!N:N,MATCH(LARGE(Watchlist!Y5:Y202,4),Watchlist!Y:Y,0)),0) | I10: =IFERROR(LARGE(Watchlist!Y5:Y202,4),0) | J10: =IFERROR(INDEX(Watchlist!Z:Z,MATCH(LARGE(Watchlist!Y5:Y202,4),Watchlist!Y:Y,0)),"") | K10: =IFERROR(LEFT(INDEX(Watchlist!AB:AB,MATCH(LARGE(Watchlist!Y5:Y202,4),Watchlist!Y:Y,0)),80),"")
B11: =IFERROR(INDEX(Watchlist!A:A,MATCH(LARGE(Watchlist!Y5:Y202,5),Watchlist!Y:Y,0)),"") | C11: =IFERROR(INDEX(Watchlist!D:D,MATCH(LARGE(Watchlist!Y5:Y202,5),Watchlist!Y:Y,0)),"") | D11: =IFERROR(INDEX(Watchlist!E:E,MATCH(LARGE(Watchlist!Y5:Y202,5),Watchlist!Y:Y,0)),"") | E11: =IFERROR(INDEX(Watchlist!H:H,MATCH(LARGE(Watchlist!Y5:Y202,5),Watchlist!Y:Y,0)),0) | F11: =IFERROR(INDEX(Watchlist!P:P,MATCH(LARGE(Watchlist!Y5:Y202,5),Watchlist!Y:Y,0)),0) | G11: =IFERROR((INDEX(Watchlist!Q:Q,MATCH(LARGE(Watchlist!Y5:Y202,5),Watchlist!Y:Y,0))/E11)-1,0) | H11: =IFERROR(INDEX(Watchlist!N:N,MATCH(LARGE(Watchlist!Y5:Y202,5),Watchlist!Y:Y,0)),0) | I11: =IFERROR(LARGE(Watchlist!Y5:Y202,5),0) | J11: =IFERROR(INDEX(Watchlist!Z:Z,MATCH(LARGE(Watchlist!Y5:Y202,5),Watchlist!Y:Y,0)),"") | K11: =IFERROR(LEFT(INDEX(Watchlist!AB:AB,MATCH(LARGE(Watchlist!Y5:Y202,5),Watchlist!Y:Y,0)),80),"")
B12: =IFERROR(INDEX(Watchlist!A:A,MATCH(LARGE(Watchlist!Y5:Y202,6),Watchlist!Y:Y,0)),"") | C12: =IFERROR(INDEX(Watchlist!D:D,MATCH(LARGE(Watchlist!Y5:Y202,6),Watchlist!Y:Y,0)),"") | D12: =IFERROR(INDEX(Watchlist!E:E,MATCH(LARGE(Watchlist!Y5:Y202,6),Watchlist!Y:Y,0)),"") | E12: =IFERROR(INDEX(Watchlist!H:H,MATCH(LARGE(Watchlist!Y5:Y202,6),Watchlist!Y:Y,0)),0) | F12: =IFERROR(INDEX(Watchlist!P:P,MATCH(LARGE(Watchlist!Y5:Y202,6),Watchlist!Y:Y,0)),0) | G12: =IFERROR((INDEX(Watchlist!Q:Q,MATCH(LARGE(Watchlist!Y5:Y202,6),Watchlist!Y:Y,0))/E12)-1,0) | H12: =IFERROR(INDEX(Watchlist!N:N,MATCH(LARGE(Watchlist!Y5:Y202,6),Watchlist!Y:Y,0)),0) | I12: =IFERROR(LARGE(Watchlist!Y5:Y202,6),0) | J12: =IFERROR(INDEX(Watchlist!Z:Z,MATCH(LARGE(Watchlist!Y5:Y202,6),Watchlist!Y:Y,0)),"") | K12: =IFERROR(LEFT(INDEX(Watchlist!AB:AB,MATCH(LARGE(Watchlist!Y5:Y202,6),Watchlist!Y:Y,0)),80),"")
B13: =IFERROR(INDEX(Watchlist!A:A,MATCH(LARGE(Watchlist!Y5:Y202,7),Watchlist!Y:Y,0)),"") | C13: =IFERROR(INDEX(Watchlist!D:D,MATCH(LARGE(Watchlist!Y5:Y202,7),Watchlist!Y:Y,0)),"") | D13: =IFERROR(INDEX(Watchlist!E:E,MATCH(LARGE(Watchlist!Y5:Y202,7),Watchlist!Y:Y,0)),"") | E13: =IFERROR(INDEX(Watchlist!H:H,MATCH(LARGE(Watchlist!Y5:Y202,7),Watchlist!Y:Y,0)),0) | F13: =IFERROR(INDEX(Watchlist!P:P,MATCH(LARGE(Watchlist!Y5:Y202,7),Watchlist!Y:Y,0)),0) | G13: =IFERROR((INDEX(Watchlist!Q:Q,MATCH(LARGE(Watchlist!Y5:Y202,7),Watchlist!Y:Y,0))/E13)-1,0) | H13: =IFERROR(INDEX(Watchlist!N:N,MATCH(LARGE(Watchlist!Y5:Y202,7),Watchlist!Y:Y,0)),0) | I13: =IFERROR(LARGE(Watchlist!Y5:Y202,7),0) | J13: =IFERROR(INDEX(Watchlist!Z:Z,MATCH(LARGE(Watchlist!Y5:Y202,7),Watchlist!Y:Y,0)),"") | K13: =IFERROR(LEFT(INDEX(Watchlist!AB:AB,MATCH(LARGE(Watchlist!Y5:Y202,7),Watchlist!Y:Y,0)),80),"")
B14: =IFERROR(INDEX(Watchlist!A:A,MATCH(LARGE(Watchlist!Y5:Y202,8),Watchlist!Y:Y,0)),"") | C14: =IFERROR(INDEX(Watchlist!D:D,MATCH(LARGE(Watchlist!Y5:Y202,8),Watchlist!Y:Y,0)),"") | D14: =IFERROR(INDEX(Watchlist!E:E,MATCH(LARGE(Watchlist!Y5:Y202,8),Watchlist!Y:Y,0)),"") | E14: =IFERROR(INDEX(Watchlist!H:H,MATCH(LARGE(Watchlist!Y5:Y202,8),Watchlist!Y:Y,0)),0) | F14: =IFERROR(INDEX(Watchlist!P:P,MATCH(LARGE(Watchlist!Y5:Y202,8),Watchlist!Y:Y,0)),0) | G14: =IFERROR((INDEX(Watchlist!Q:Q,MATCH(LARGE(Watchlist!Y5:Y202,8),Watchlist!Y:Y,0))/E14)-1,0) | H14: =IFERROR(INDEX(Watchlist!N:N,MATCH(LARGE(Watchlist!Y5:Y202,8),Watchlist!Y:Y,0)),0) | I14: =IFERROR(LARGE(Watchlist!Y5:Y202,8),0) | J14: =IFERROR(INDEX(Watchlist!Z:Z,MATCH(LARGE(Watchlist!Y5:Y202,8),Watchlist!Y:Y,0)),"") | K14: =IFERROR(LEFT(INDEX(Watchlist!AB:AB,MATCH(LARGE(Watchlist!Y5:Y202,8),Watchlist!Y:Y,0)),80),"")
B15: =IFERROR(INDEX(Watchlist!A:A,MATCH(LARGE(Watchlist!Y5:Y202,9),Watchlist!Y:Y,0)),"") | C15: =IFERROR(INDEX(Watchlist!D:D,MATCH(LARGE(Watchlist!Y5:Y202,9),Watchlist!Y:Y,0)),"") | D15: =IFERROR(INDEX(Watchlist!E:E,MATCH(LARGE(Watchlist!Y5:Y202,9),Watchlist!Y:Y,0)),"") | E15: =IFERROR(INDEX(Watchlist!H:H,MATCH(LARGE(Watchlist!Y5:Y202,9),Watchlist!Y:Y,0)),0) | F15: =IFERROR(INDEX(Watchlist!P:P,MATCH(LARGE(Watchlist!Y5:Y202,9),Watchlist!Y:Y,0)),0) | G15: =IFERROR((INDEX(Watchlist!Q:Q,MATCH(LARGE(Watchlist!Y5:Y202,9),Watchlist!Y:Y,0))/E15)-1,0) | H15: =IFERROR(INDEX(Watchlist!N:N,MATCH(LARGE(Watchlist!Y5:Y202,9),Watchlist!Y:Y,0)),0) | I15: =IFERROR(LARGE(Watchlist!Y5:Y202,9),0) | J15: =IFERROR(INDEX(Watchlist!Z:Z,MATCH(LARGE(Watchlist!Y5:Y202,9),Watchlist!Y:Y,0)),"") | K15: =IFERROR(LEFT(INDEX(Watchlist!AB:AB,MATCH(LARGE(Watchlist!Y5:Y202,9),Watchlist!Y:Y,0)),80),"")
B16: =IFERROR(INDEX(Watchlist!A:A,MATCH(LARGE(Watchlist!Y5:Y202,10),Watchlist!Y:Y,0)),"") | C16: =IFERROR(INDEX(Watchlist!D:D,MATCH(LARGE(Watchlist!Y5:Y202,10),Watchlist!Y:Y,0)),"") | D16: =IFERROR(INDEX(Watchlist!E:E,MATCH(LARGE(Watchlist!Y5:Y202,10),Watchlist!Y:Y,0)),"") | E16: =IFERROR(INDEX(Watchlist!H:H,MATCH(LARGE(Watchlist!Y5:Y202,10),Watchlist!Y:Y,0)),0) | F16: =IFERROR(INDEX(Watchlist!P:P,MATCH(LARGE(Watchlist!Y5:Y202,10),Watchlist!Y:Y,0)),0) | G16: =IFERROR((INDEX(Watchlist!Q:Q,MATCH(LARGE(Watchlist!Y5:Y202,10),Watchlist!Y:Y,0))/E16)-1,0) | H16: =IFERROR(INDEX(Watchlist!N:N,MATCH(LARGE(Watchlist!Y5:Y202,10),Watchlist!Y:Y,0)),0) | I16: =IFERROR(LARGE(Watchlist!Y5:Y202,10),0) | J16: =IFERROR(INDEX(Watchlist!Z:Z,MATCH(LARGE(Watchlist!Y5:Y202,10),Watchlist!Y:Y,0)),"") | K16: =IFERROR(LEFT(INDEX(Watchlist!AB:AB,MATCH(LARGE(Watchlist!Y5:Y202,10),Watchlist!Y:Y,0)),80),"")
B18: TOP 5 SELL / TRIM SIGNALS
B19: CardID | C19: Card Name | D19: Set | E19: Current Price | F19: Target Buy | G19: Upside to Sell | H19: 30D % | I19: Score | J19: Signal | K19: Why
B20: =IFERROR(INDEX(Watchlist!A:A,MATCH(SMALL(Watchlist!Y5:Y202,1),Watchlist!Y:Y,0)),"") | C20: =IFERROR(INDEX(Watchlist!D:D,MATCH(SMALL(Watchlist!Y5:Y202,1),Watchlist!Y:Y,0)),"") | D20: =IFERROR(INDEX(Watchlist!E:E,MATCH(SMALL(Watchlist!Y5:Y202,1),Watchlist!Y:Y,0)),"") | E20: =IFERROR(INDEX(Watchlist!H:H,MATCH(SMALL(Watchlist!Y5:Y202,1),Watchlist!Y:Y,0)),0) | F20: =IFERROR(INDEX(Watchlist!P:P,MATCH(SMALL(Watchlist!Y5:Y202,1),Watchlist!Y:Y,0)),0) | G20: =IFERROR((INDEX(Watchlist!Q:Q,MATCH(SMALL(Watchlist!Y5:Y202,1),Watchlist!Y:Y,0))/E20)-1,0) | H20: =IFERROR(INDEX(Watchlist!N:N,MATCH(SMALL(Watchlist!Y5:Y202,1),Watchlist!Y:Y,0)),0) | I20: =IFERROR(SMALL(Watchlist!Y5:Y202,1),0) | J20: =IFERROR(INDEX(Watchlist!Z:Z,MATCH(SMALL(Watchlist!Y5:Y202,1),Watchlist!Y:Y,0)),"") | K20: =IFERROR(LEFT(INDEX(Watchlist!AB:AB,MATCH(SMALL(Watchlist!Y5:Y202,1),Watchlist!Y:Y,0)),80),"")
B21: =IFERROR(INDEX(Watchlist!A:A,MATCH(SMALL(Watchlist!Y5:Y202,2),Watchlist!Y:Y,0)),"") | C21: =IFERROR(INDEX(Watchlist!D:D,MATCH(SMALL(Watchlist!Y5:Y202,2),Watchlist!Y:Y,0)),"") | D21: =IFERROR(INDEX(Watchlist!E:E,MATCH(SMALL(Watchlist!Y5:Y202,2),Watchlist!Y:Y,0)),"") | E21: =IFERROR(INDEX(Watchlist!H:H,MATCH(SMALL(Watchlist!Y5:Y202,2),Watchlist!Y:Y,0)),0) | F21: =IFERROR(INDEX(Watchlist!P:P,MATCH(SMALL(Watchlist!Y5:Y202,2),Watchlist!Y:Y,0)),0) | G21: =IFERROR((INDEX(Watchlist!Q:Q,MATCH(SMALL(Watchlist!Y5:Y202,2),Watchlist!Y:Y,0))/E21)-1,0) | H21: =IFERROR(INDEX(Watchlist!N:N,MATCH(SMALL(Watchlist!Y5:Y202,2),Watchlist!Y:Y,0)),0) | I21: =IFERROR(SMALL(Watchlist!Y5:Y202,2),0) | J21: =IFERROR(INDEX(Watchlist!Z:Z,MATCH(SMALL(Watchlist!Y5:Y202,2),Watchlist!Y:Y,0)),"") | K21: =IFERROR(LEFT(INDEX(Watchlist!AB:AB,MATCH(SMALL(Watchlist!Y5:Y202,2),Watchlist!Y:Y,0)),80),"")
B22: =IFERROR(INDEX(Watchlist!A:A,MATCH(SMALL(Watchlist!Y5:Y202,3),Watchlist!Y:Y,0)),"") | C22: =IFERROR(INDEX(Watchlist!D:D,MATCH(SMALL(Watchlist!Y5:Y202,3),Watchlist!Y:Y,0)),"") | D22: =IFERROR(INDEX(Watchlist!E:E,MATCH(SMALL(Watchlist!Y5:Y202,3),Watchlist!Y:Y,0)),"") | E22: =IFERROR(INDEX(Watchlist!H:H,MATCH(SMALL(Watchlist!Y5:Y202,3),Watchlist!Y:Y,0)),0) | F22: =IFERROR(INDEX(Watchlist!P:P,MATCH(SMALL(Watchlist!Y5:Y202,3),Watchlist!Y:Y,0)),0) | G22: =IFERROR((INDEX(Watchlist!Q:Q,MATCH(SMALL(Watchlist!Y5:Y202,3),Watchlist!Y:Y,0))/E22)-1,0) | H22: =IFERROR(INDEX(Watchlist!N:N,MATCH(SMALL(Watchlist!Y5:Y202,3),Watchlist!Y:Y,0)),0) | I22: =IFERROR(SMALL(Watchlist!Y5:Y202,3),0) | J22: =IFERROR(INDEX(Watchlist!Z:Z,MATCH(SMALL(Watchlist!Y5:Y202,3),Watchlist!Y:Y,0)),"") | K22: =IFERROR(LEFT(INDEX(Watchlist!AB:AB,MATCH(SMALL(Watchlist!Y5:Y202,3),Watchlist!Y:Y,0)),80),"")
B23: =IFERROR(INDEX(Watchlist!A:A,MATCH(SMALL(Watchlist!Y5:Y202,4),Watchlist!Y:Y,0)),"") | C23: =IFERROR(INDEX(Watchlist!D:D,MATCH(SMALL(Watchlist!Y5:Y202,4),Watchlist!Y:Y,0)),"") | D23: =IFERROR(INDEX(Watchlist!E:E,MATCH(SMALL(Watchlist!Y5:Y202,4),Watchlist!Y:Y,0)),"") | E23: =IFERROR(INDEX(Watchlist!H:H,MATCH(SMALL(Watchlist!Y5:Y202,4),Watchlist!Y:Y,0)),0) | F23: =IFERROR(INDEX(Watchlist!P:P,MATCH(SMALL(Watchlist!Y5:Y202,4),Watchlist!Y:Y,0)),0) | G23: =IFERROR((INDEX(Watchlist!Q:Q,MATCH(SMALL(Watchlist!Y5:Y202,4),Watchlist!Y:Y,0))/E23)-1,0) | H23: =IFERROR(INDEX(Watchlist!N:N,MATCH(SMALL(Watchlist!Y5:Y202,4),Watchlist!Y:Y,0)),0) | I23: =IFERROR(SMALL(Watchlist!Y5:Y202,4),0) | J23: =IFERROR(INDEX(Watchlist!Z:Z,MATCH(SMALL(Watchlist!Y5:Y202,4),Watchlist!Y:Y,0)),"") | K23: =IFERROR(LEFT(INDEX(Watchlist!AB:AB,MATCH(SMALL(Watchlist!Y5:Y202,4),Watchlist!Y:Y,0)),80),"")
B24: =IFERROR(INDEX(Watchlist!A:A,MATCH(SMALL(Watchlist!Y5:Y202,5),Watchlist!Y:Y,0)),"") | C24: =IFERROR(INDEX(Watchlist!D:D,MATCH(SMALL(Watchlist!Y5:Y202,5),Watchlist!Y:Y,0)),"") | D24: =IFERROR(INDEX(Watchlist!E:E,MATCH(SMALL(Watchlist!Y5:Y202,5),Watchlist!Y:Y,0)),"") | E24: =IFERROR(INDEX(Watchlist!H:H,MATCH(SMALL(Watchlist!Y5:Y202,5),Watchlist!Y:Y,0)),0) | F24: =IFERROR(INDEX(Watchlist!P:P,MATCH(SMALL(Watchlist!Y5:Y202,5),Watchlist!Y:Y,0)),0) | G24: =IFERROR((INDEX(Watchlist!Q:Q,MATCH(SMALL(Watchlist!Y5:Y202,5),Watchlist!Y:Y,0))/E24)-1,0) | H24: =IFERROR(INDEX(Watchlist!N:N,MATCH(SMALL(Watchlist!Y5:Y202,5),Watchlist!Y:Y,0)),0) | I24: =IFERROR(SMALL(Watchlist!Y5:Y202,5),0) | J24: =IFERROR(INDEX(Watchlist!Z:Z,MATCH(SMALL(Watchlist!Y5:Y202,5),Watchlist!Y:Y,0)),"") | K24: =IFERROR(LEFT(INDEX(Watchlist!AB:AB,MATCH(SMALL(Watchlist!Y5:Y202,5),Watchlist!Y:Y,0)),80),"")
B27: WEEKLY DEPLOYMENT SUMMARY
B28: Available Cash this Week | C28: 1500 | D28: ← edit to your weekly contribution
B29: # Strong Buy signals on Watchlist | C29: =COUNTIF(Watchlist!Z5:Z202,"STRONG BUY")
B30: # Buy signals on Watchlist | C30: =COUNTIF(Watchlist!Z5:Z202,"BUY")
B31: # Trim/Sell signals on Watchlist | C31: =COUNTIF(Watchlist!Z5:Z202,"TRIM")+COUNTIF(Watchlist!Z5:Z202,"SELL")
B32: Avg Composite Score (all 198) | C32: =AVERAGE(Watchlist!Y5:Y202)
B33: Market Heat Reading | C33: =IF(C32>=65,"HOT - selective buying",IF(C32>=50,"BALANCED",IF(C32>=40,"COOL - load up","FROZEN - bargain hunt")))

Sheet Hot Singles
B2: HOT SINGLES — Momentum Leaders
B3: Top 20 cards sorted by 30-day price change. Refreshes when Price History updates.
B5: TOP 20 MOMENTUM (by 30D %)
B6: CardID | C6: Card Name | D6: Set | E6: Current Price | F6: Variant | G6: 7D % | H6: 30D % | I6: 90D % | J6: Score | K6: Signal
B7: =IFERROR(INDEX(Watchlist!A:A,MATCH(LARGE(Watchlist!N5:N202,1),Watchlist!N:N,0)),"") | C7: =IFERROR(INDEX(Watchlist!D:D,MATCH(LARGE(Watchlist!N5:N202,1),Watchlist!N:N,0)),"") | D7: =IFERROR(INDEX(Watchlist!E:E,MATCH(LARGE(Watchlist!N5:N202,1),Watchlist!N:N,0)),"") | E7: =IFERROR(INDEX(Watchlist!H:H,MATCH(LARGE(Watchlist!N5:N202,1),Watchlist!N:N,0)),0) | F7: =IFERROR(INDEX(Watchlist!G:G,MATCH(LARGE(Watchlist!N5:N202,1),Watchlist!N:N,0)),"") | G7: =IFERROR(INDEX(Watchlist!M:M,MATCH(LARGE(Watchlist!N5:N202,1),Watchlist!N:N,0)),0) | H7: =IFERROR(LARGE(Watchlist!N5:N202,1),0) | I7: =IFERROR(INDEX(Watchlist!O:O,MATCH(LARGE(Watchlist!N5:N202,1),Watchlist!N:N,0)),0) | J7: =IFERROR(INDEX(Watchlist!Y:Y,MATCH(LARGE(Watchlist!N5:N202,1),Watchlist!N:N,0)),0) | K7: =IFERROR(INDEX(Watchlist!Z:Z,MATCH(LARGE(Watchlist!N5:N202,1),Watchlist!N:N,0)),"")
B8: =IFERROR(INDEX(Watchlist!A:A,MATCH(LARGE(Watchlist!N5:N202,2),Watchlist!N:N,0)),"") | C8: =IFERROR(INDEX(Watchlist!D:D,MATCH(LARGE(Watchlist!N5:N202,2),Watchlist!N:N,0)),"") | D8: =IFERROR(INDEX(Watchlist!E:E,MATCH(LARGE(Watchlist!N5:N202,2),Watchlist!N:N,0)),"") | E8: =IFERROR(INDEX(Watchlist!H:H,MATCH(LARGE(Watchlist!N5:N202,2),Watchlist!N:N,0)),0) | F8: =IFERROR(INDEX(Watchlist!G:G,MATCH(LARGE(Watchlist!N5:N202,2),Watchlist!N:N,0)),"") | G8: =IFERROR(INDEX(Watchlist!M:M,MATCH(LARGE(Watchlist!N5:N202,2),Watchlist!N:N,0)),0) | H8: =IFERROR(LARGE(Watchlist!N5:N202,2),0) | I8: =IFERROR(INDEX(Watchlist!O:O,MATCH(LARGE(Watchlist!N5:N202,2),Watchlist!N:N,0)),0) | J8: =IFERROR(INDEX(Watchlist!Y:Y,MATCH(LARGE(Watchlist!N5:N202,2),Watchlist!N:N,0)),0) | K8: =IFERROR(INDEX(Watchlist!Z:Z,MATCH(LARGE(Watchlist!N5:N202,2),Watchlist!N:N,0)),"")
B9: =IFERROR(INDEX(Watchlist!A:A,MATCH(LARGE(Watchlist!N5:N202,3),Watchlist!N:N,0)),"") | C9: =IFERROR(INDEX(Watchlist!D:D,MATCH(LARGE(Watchlist!N5:N202,3),Watchlist!N:N,0)),"") | D9: =IFERROR(INDEX(Watchlist!E:E,MATCH(LARGE(Watchlist!N5:N202,3),Watchlist!N:N,0)),"") | E9: =IFERROR(INDEX(Watchlist!H:H,MATCH(LARGE(Watchlist!N5:N202,3),Watchlist!N:N,0)),0) | F9: =IFERROR(INDEX(Watchlist!G:G,MATCH(LARGE(Watchlist!N5:N202,3),Watchlist!N:N,0)),"") | G9: =IFERROR(INDEX(Watchlist!M:M,MATCH(LARGE(Watchlist!N5:N202,3),Watchlist!N:N,0)),0) | H9: =IFERROR(LARGE(Watchlist!N5:N202,3),0) | I9: =IFERROR(INDEX(Watchlist!O:O,MATCH(LARGE(Watchlist!N5:N202,3),Watchlist!N:N,0)),0) | J9: =IFERROR(INDEX(Watchlist!Y:Y,MATCH(LARGE(Watchlist!N5:N202,3),Watchlist!N:N,0)),0) | K9: =IFERROR(INDEX(Watchlist!Z:Z,MATCH(LARGE(Watchlist!N5:N202,3),Watchlist!N:N,0)),"")
B10: =IFERROR(INDEX(Watchlist!A:A,MATCH(LARGE(Watchlist!N5:N202,4),Watchlist!N:N,0)),"") | C10: =IFERROR(INDEX(Watchlist!D:D,MATCH(LARGE(Watchlist!N5:N202,4),Watchlist!N:N,0)),"") | D10: =IFERROR(INDEX(Watchlist!E:E,MATCH(LARGE(Watchlist!N5:N202,4),Watchlist!N:N,0)),"") | E10: =IFERROR(INDEX(Watchlist!H:H,MATCH(LARGE(Watchlist!N5:N202,4),Watchlist!N:N,0)),0) | F10: =IFERROR(INDEX(Watchlist!G:G,MATCH(LARGE(Watchlist!N5:N202,4),Watchlist!N:N,0)),"") | G10: =IFERROR(INDEX(Watchlist!M:M,MATCH(LARGE(Watchlist!N5:N202,4),Watchlist!N:N,0)),0) | H10: =IFERROR(LARGE(Watchlist!N5:N202,4),0) | I10: =IFERROR(INDEX(Watchlist!O:O,MATCH(LARGE(Watchlist!N5:N202,4),Watchlist!N:N,0)),0) | J10: =IFERROR(INDEX(Watchlist!Y:Y,MATCH(LARGE(Watchlist!N5:N202,4),Watchlist!N:N,0)),0) | K10: =IFERROR(INDEX(Watchlist!Z:Z,MATCH(LARGE(Watchlist!N5:N202,4),Watchlist!N:N,0)),"")
B11: =IFERROR(INDEX(Watchlist!A:A,MATCH(LARGE(Watchlist!N5:N202,5),Watchlist!N:N,0)),"") | C11: =IFERROR(INDEX(Watchlist!D:D,MATCH(LARGE(Watchlist!N5:N202,5),Watchlist!N:N,0)),"") | D11: =IFERROR(INDEX(Watchlist!E:E,MATCH(LARGE(Watchlist!N5:N202,5),Watchlist!N:N,0)),"") | E11: =IFERROR(INDEX(Watchlist!H:H,MATCH(LARGE(Watchlist!N5:N202,5),Watchlist!N:N,0)),0) | F11: =IFERROR(INDEX(Watchlist!G:G,MATCH(LARGE(Watchlist!N5:N202,5),Watchlist!N:N,0)),"") | G11: =IFERROR(INDEX(Watchlist!M:M,MATCH(LARGE(Watchlist!N5:N202,5),Watchlist!N:N,0)),0) | H11: =IFERROR(LARGE(Watchlist!N5:N202,5),0) | I11: =IFERROR(INDEX(Watchlist!O:O,MATCH(LARGE(Watchlist!N5:N202,5),Watchlist!N:N,0)),0) | J11: =IFERROR(INDEX(Watchlist!Y:Y,MATCH(LARGE(Watchlist!N5:N202,5),Watchlist!N:N,0)),0) | K11: =IFERROR(INDEX(Watchlist!Z:Z,MATCH(LARGE(Watchlist!N5:N202,5),Watchlist!N:N,0)),"")
B12: =IFERROR(INDEX(Watchlist!A:A,MATCH(LARGE(Watchlist!N5:N202,6),Watchlist!N:N,0)),"") | C12: =IFERROR(INDEX(Watchlist!D:D,MATCH(LARGE(Watchlist!N5:N202,6),Watchlist!N:N,0)),"") | D12: =IFERROR(INDEX(Watchlist!E:E,MATCH(LARGE(Watchlist!N5:N202,6),Watchlist!N:N,0)),"") | E12: =IFERROR(INDEX(Watchlist!H:H,MATCH(LARGE(Watchlist!N5:N202,6),Watchlist!N:N,0)),0) | F12: =IFERROR(INDEX(Watchlist!G:G,MATCH(LARGE(Watchlist!N5:N202,6),Watchlist!N:N,0)),"") | G12: =IFERROR(INDEX(Watchlist!M:M,MATCH(LARGE(Watchlist!N5:N202,6),Watchlist!N:N,0)),0) | H12: =IFERROR(LARGE(Watchlist!N5:N202,6),0) | I12: =IFERROR(INDEX(Watchlist!O:O,MATCH(LARGE(Watchlist!N5:N202,6),Watchlist!N:N,0)),0) | J12: =IFERROR(INDEX(Watchlist!Y:Y,MATCH(LARGE(Watchlist!N5:N202,6),Watchlist!N:N,0)),0) | K12: =IFERROR(INDEX(Watchlist!Z:Z,MATCH(LARGE(Watchlist!N5:N202,6),Watchlist!N:N,0)),"")
B13: =IFERROR(INDEX(Watchlist!A:A,MATCH(LARGE(Watchlist!N5:N202,7),Watchlist!N:N,0)),"") | C13: =IFERROR(INDEX(Watchlist!D:D,MATCH(LARGE(Watchlist!N5:N202,7),Watchlist!N:N,0)),"") | D13: =IFERROR(INDEX(Watchlist!E:E,MATCH(LARGE(Watchlist!N5:N202,7),Watchlist!N:N,0)),"") | E13: =IFERROR(INDEX(Watchlist!H:H,MATCH(LARGE(Watchlist!N5:N202,7),Watchlist!N:N,0)),0) | F13: =IFERROR(INDEX(Watchlist!G:G,MATCH(LARGE(Watchlist!N5:N202,7),Watchlist!N:N,0)),"") | G13: =IFERROR(INDEX(Watchlist!M:M,MATCH(LARGE(Watchlist!N5:N202,7),Watchlist!N:N,0)),0) | H13: =IFERROR(LARGE(Watchlist!N5:N202,7),0) | I13: =IFERROR(INDEX(Watchlist!O:O,MATCH(LARGE(Watchlist!N5:N202,7),Watchlist!N:N,0)),0) | J13: =IFERROR(INDEX(Watchlist!Y:Y,MATCH(LARGE(Watchlist!N5:N202,7),Watchlist!N:N,0)),0) | K13: =IFERROR(INDEX(Watchlist!Z:Z,MATCH(LARGE(Watchlist!N5:N202,7),Watchlist!N:N,0)),"")
B14: =IFERROR(INDEX(Watchlist!A:A,MATCH(LARGE(Watchlist!N5:N202,8),Watchlist!N:N,0)),"") | C14: =IFERROR(INDEX(Watchlist!D:D,MATCH(LARGE(Watchlist!N5:N202,8),Watchlist!N:N,0)),"") | D14: =IFERROR(INDEX(Watchlist!E:E,MATCH(LARGE(Watchlist!N5:N202,8),Watchlist!N:N,0)),"") | E14: =IFERROR(INDEX(Watchlist!H:H,MATCH(LARGE(Watchlist!N5:N202,8),Watchlist!N:N,0)),0) | F14: =IFERROR(INDEX(Watchlist!G:G,MATCH(LARGE(Watchlist!N5:N202,8),Watchlist!N:N,0)),"") | G14: =IFERROR(INDEX(Watchlist!M:M,MATCH(LARGE(Watchlist!N5:N202,8),Watchlist!N:N,0)),0) | H14: =IFERROR(LARGE(Watchlist!N5:N202,8),0) | I14: =IFERROR(INDEX(Watchlist!O:O,MATCH(LARGE(Watchlist!N5:N202,8),Watchlist!N:N,0)),0) | J14: =IFERROR(INDEX(Watchlist!Y:Y,MATCH(LARGE(Watchlist!N5:N202,8),Watchlist!N:N,0)),0) | K14: =IFERROR(INDEX(Watchlist!Z:Z,MATCH(LARGE(Watchlist!N5:N202,8),Watchlist!N:N,0)),"")
B15: =IFERROR(INDEX(Watchlist!A:A,MATCH(LARGE(Watchlist!N5:N202,9),Watchlist!N:N,0)),"") | C15: =IFERROR(INDEX(Watchlist!D:D,MATCH(LARGE(Watchlist!N5:N202,9),Watchlist!N:N,0)),"") | D15: =IFERROR(INDEX(Watchlist!E:E,MATCH(LARGE(Watchlist!N5:N202,9),Watchlist!N:N,0)),"") | E15: =IFERROR(INDEX(Watchlist!H:H,MATCH(LARGE(Watchlist!N5:N202,9),Watchlist!N:N,0)),0) | F15: =IFERROR(INDEX(Watchlist!G:G,MATCH(LARGE(Watchlist!N5:N202,9),Watchlist!N:N,0)),"") | G15: =IFERROR(INDEX(Watchlist!M:M,MATCH(LARGE(Watchlist!N5:N202,9),Watchlist!N:N,0)),0) | H15: =IFERROR(LARGE(Watchlist!N5:N202,9),0) | I15: =IFERROR(INDEX(Watchlist!O:O,MATCH(LARGE(Watchlist!N5:N202,9),Watchlist!N:N,0)),0) | J15: =IFERROR(INDEX(Watchlist!Y:Y,MATCH(LARGE(Watchlist!N5:N202,9),Watchlist!N:N,0)),0) | K15: =IFERROR(INDEX(Watchlist!Z:Z,MATCH(LARGE(Watchlist!N5:N202,9),Watchlist!N:N,0)),"")
B16: =IFERROR(INDEX(Watchlist!A:A,MATCH(LARGE(Watchlist!N5:N202,10),Watchlist!N:N,0)),"") | C16: =IFERROR(INDEX(Watchlist!D:D,MATCH(LARGE(Watchlist!N5:N202,10),Watchlist!N:N,0)),"") | D16: =IFERROR(INDEX(Watchlist!E:E,MATCH(LARGE(Watchlist!N5:N202,10),Watchlist!N:N,0)),"") | E16: =IFERROR(INDEX(Watchlist!H:H,MATCH(LARGE(Watchlist!N5:N202,10),Watchlist!N:N,0)),0) | F16: =IFERROR(INDEX(Watchlist!G:G,MATCH(LARGE(Watchlist!N5:N202,10),Watchlist!N:N,0)),"") | G16: =IFERROR(INDEX(Watchlist!M:M,MATCH(LARGE(Watchlist!N5:N202,10),Watchlist!N:N,0)),0) | H16: =IFERROR(LARGE(Watchlist!N5:N202,10),0) | I16: =IFERROR(INDEX(Watchlist!O:O,MATCH(LARGE(Watchlist!N5:N202,10),Watchlist!N:N,0)),0) | J16: =IFERROR(INDEX(Watchlist!Y:Y,MATCH(LARGE(Watchlist!N5:N202,10),Watchlist!N:N,0)),0) | K16: =IFERROR(INDEX(Watchlist!Z:Z,MATCH(LARGE(Watchlist!N5:N202,10),Watchlist!N:N,0)),"")
B17: =IFERROR(INDEX(Watchlist!A:A,MATCH(LARGE(Watchlist!N5:N202,11),Watchlist!N:N,0)),"") | C17: =IFERROR(INDEX(Watchlist!D:D,MATCH(LARGE(Watchlist!N5:N202,11),Watchlist!N:N,0)),"") | D17: =IFERROR(INDEX(Watchlist!E:E,MATCH(LARGE(Watchlist!N5:N202,11),Watchlist!N:N,0)),"") | E17: =IFERROR(INDEX(Watchlist!H:H,MATCH(LARGE(Watchlist!N5:N202,11),Watchlist!N:N,0)),0) | F17: =IFERROR(INDEX(Watchlist!G:G,MATCH(LARGE(Watchlist!N5:N202,11),Watchlist!N:N,0)),"") | G17: =IFERROR(INDEX(Watchlist!M:M,MATCH(LARGE(Watchlist!N5:N202,11),Watchlist!N:N,0)),0) | H17: =IFERROR(LARGE(Watchlist!N5:N202,11),0) | I17: =IFERROR(INDEX(Watchlist!O:O,MATCH(LARGE(Watchlist!N5:N202,11),Watchlist!N:N,0)),0) | J17: =IFERROR(INDEX(Watchlist!Y:Y,MATCH(LARGE(Watchlist!N5:N202,11),Watchlist!N:N,0)),0) | K17: =IFERROR(INDEX(Watchlist!Z:Z,MATCH(LARGE(Watchlist!N5:N202,11),Watchlist!N:N,0)),"")
B18: =IFERROR(INDEX(Watchlist!A:A,MATCH(LARGE(Watchlist!N5:N202,12),Watchlist!N:N,0)),"") | C18: =IFERROR(INDEX(Watchlist!D:D,MATCH(LARGE(Watchlist!N5:N202,12),Watchlist!N:N,0)),"") | D18: =IFERROR(INDEX(Watchlist!E:E,MATCH(LARGE(Watchlist!N5:N202,12),Watchlist!N:N,0)),"") | E18: =IFERROR(INDEX(Watchlist!H:H,MATCH(LARGE(Watchlist!N5:N202,12),Watchlist!N:N,0)),0) | F18: =IFERROR(INDEX(Watchlist!G:G,MATCH(LARGE(Watchlist!N5:N202,12),Watchlist!N:N,0)),"") | G18: =IFERROR(INDEX(Watchlist!M:M,MATCH(LARGE(Watchlist!N5:N202,12),Watchlist!N:N,0)),0) | H18: =IFERROR(LARGE(Watchlist!N5:N202,12),0) | I18: =IFERROR(INDEX(Watchlist!O:O,MATCH(LARGE(Watchlist!N5:N202,12),Watchlist!N:N,0)),0) | J18: =IFERROR(INDEX(Watchlist!Y:Y,MATCH(LARGE(Watchlist!N5:N202,12),Watchlist!N:N,0)),0) | K18: =IFERROR(INDEX(Watchlist!Z:Z,MATCH(LARGE(Watchlist!N5:N202,12),Watchlist!N:N,0)),"")
B19: =IFERROR(INDEX(Watchlist!A:A,MATCH(LARGE(Watchlist!N5:N202,13),Watchlist!N:N,0)),"") | C19: =IFERROR(INDEX(Watchlist!D:D,MATCH(LARGE(Watchlist!N5:N202,13),Watchlist!N:N,0)),"") | D19: =IFERROR(INDEX(Watchlist!E:E,MATCH(LARGE(Watchlist!N5:N202,13),Watchlist!N:N,0)),"") | E19: =IFERROR(INDEX(Watchlist!H:H,MATCH(LARGE(Watchlist!N5:N202,13),Watchlist!N:N,0)),0) | F19: =IFERROR(INDEX(Watchlist!G:G,MATCH(LARGE(Watchlist!N5:N202,13),Watchlist!N:N,0)),"") | G19: =IFERROR(INDEX(Watchlist!M:M,MATCH(LARGE(Watchlist!N5:N202,13),Watchlist!N:N,0)),0) | H19: =IFERROR(LARGE(Watchlist!N5:N202,13),0) | I19: =IFERROR(INDEX(Watchlist!O:O,MATCH(LARGE(Watchlist!N5:N202,13),Watchlist!N:N,0)),0) | J19: =IFERROR(INDEX(Watchlist!Y:Y,MATCH(LARGE(Watchlist!N5:N202,13),Watchlist!N:N,0)),0) | K19: =IFERROR(INDEX(Watchlist!Z:Z,MATCH(LARGE(Watchlist!N5:N202,13),Watchlist!N:N,0)),"")
B20: =IFERROR(INDEX(Watchlist!A:A,MATCH(LARGE(Watchlist!N5:N202,14),Watchlist!N:N,0)),"") | C20: =IFERROR(INDEX(Watchlist!D:D,MATCH(LARGE(Watchlist!N5:N202,14),Watchlist!N:N,0)),"") | D20: =IFERROR(INDEX(Watchlist!E:E,MATCH(LARGE(Watchlist!N5:N202,14),Watchlist!N:N,0)),"") | E20: =IFERROR(INDEX(Watchlist!H:H,MATCH(LARGE(Watchlist!N5:N202,14),Watchlist!N:N,0)),0) | F20: =IFERROR(INDEX(Watchlist!G:G,MATCH(LARGE(Watchlist!N5:N202,14),Watchlist!N:N,0)),"") | G20: =IFERROR(INDEX(Watchlist!M:M,MATCH(LARGE(Watchlist!N5:N202,14),Watchlist!N:N,0)),0) | H20: =IFERROR(LARGE(Watchlist!N5:N202,14),0) | I20: =IFERROR(INDEX(Watchlist!O:O,MATCH(LARGE(Watchlist!N5:N202,14),Watchlist!N:N,0)),0) | J20: =IFERROR(INDEX(Watchlist!Y:Y,MATCH(LARGE(Watchlist!N5:N202,14),Watchlist!N:N,0)),0) | K20: =IFERROR(INDEX(Watchlist!Z:Z,MATCH(LARGE(Watchlist!N5:N202,14),Watchlist!N:N,0)),"")
B21: =IFERROR(INDEX(Watchlist!A:A,MATCH(LARGE(Watchlist!N5:N202,15),Watchlist!N:N,0)),"") | C21: =IFERROR(INDEX(Watchlist!D:D,MATCH(LARGE(Watchlist!N5:N202,15),Watchlist!N:N,0)),"") | D21: =IFERROR(INDEX(Watchlist!E:E,MATCH(LARGE(Watchlist!N5:N202,15),Watchlist!N:N,0)),"") | E21: =IFERROR(INDEX(Watchlist!H:H,MATCH(LARGE(Watchlist!N5:N202,15),Watchlist!N:N,0)),0) | F21: =IFERROR(INDEX(Watchlist!G:G,MATCH(LARGE(Watchlist!N5:N202,15),Watchlist!N:N,0)),"") | G21: =IFERROR(INDEX(Watchlist!M:M,MATCH(LARGE(Watchlist!N5:N202,15),Watchlist!N:N,0)),0) | H21: =IFERROR(LARGE(Watchlist!N5:N202,15),0) | I21: =IFERROR(INDEX(Watchlist!O:O,MATCH(LARGE(Watchlist!N5:N202,15),Watchlist!N:N,0)),0) | J21: =IFERROR(INDEX(Watchlist!Y:Y,MATCH(LARGE(Watchlist!N5:N202,15),Watchlist!N:N,0)),0) | K21: =IFERROR(INDEX(Watchlist!Z:Z,MATCH(LARGE(Watchlist!N5:N202,15),Watchlist!N:N,0)),"")
B22: =IFERROR(INDEX(Watchlist!A:A,MATCH(LARGE(Watchlist!N5:N202,16),Watchlist!N:N,0)),"") | C22: =IFERROR(INDEX(Watchlist!D:D,MATCH(LARGE(Watchlist!N5:N202,16),Watchlist!N:N,0)),"") | D22: =IFERROR(INDEX(Watchlist!E:E,MATCH(LARGE(Watchlist!N5:N202,16),Watchlist!N:N,0)),"") | E22: =IFERROR(INDEX(Watchlist!H:H,MATCH(LARGE(Watchlist!N5:N202,16),Watchlist!N:N,0)),0) | F22: =IFERROR(INDEX(Watchlist!G:G,MATCH(LARGE(Watchlist!N5:N202,16),Watchlist!N:N,0)),"") | G22: =IFERROR(INDEX(Watchlist!M:M,MATCH(LARGE(Watchlist!N5:N202,16),Watchlist!N:N,0)),0) | H22: =IFERROR(LARGE(Watchlist!N5:N202,16),0) | I22: =IFERROR(INDEX(Watchlist!O:O,MATCH(LARGE(Watchlist!N5:N202,16),Watchlist!N:N,0)),0) | J22: =IFERROR(INDEX(Watchlist!Y:Y,MATCH(LARGE(Watchlist!N5:N202,16),Watchlist!N:N,0)),0) | K22: =IFERROR(INDEX(Watchlist!Z:Z,MATCH(LARGE(Watchlist!N5:N202,16),Watchlist!N:N,0)),"")
B23: =IFERROR(INDEX(Watchlist!A:A,MATCH(LARGE(Watchlist!N5:N202,17),Watchlist!N:N,0)),"") | C23: =IFERROR(INDEX(Watchlist!D:D,MATCH(LARGE(Watchlist!N5:N202,17),Watchlist!N:N,0)),"") | D23: =IFERROR(INDEX(Watchlist!E:E,MATCH(LARGE(Watchlist!N5:N202,17),Watchlist!N:N,0)),"") | E23: =IFERROR(INDEX(Watchlist!H:H,MATCH(LARGE(Watchlist!N5:N202,17),Watchlist!N:N,0)),0) | F23: =IFERROR(INDEX(Watchlist!G:G,MATCH(LARGE(Watchlist!N5:N202,17),Watchlist!N:N,0)),"") | G23: =IFERROR(INDEX(Watchlist!M:M,MATCH(LARGE(Watchlist!N5:N202,17),Watchlist!N:N,0)),0) | H23: =IFERROR(LARGE(Watchlist!N5:N202,17),0) | I23: =IFERROR(INDEX(Watchlist!O:O,MATCH(LARGE(Watchlist!N5:N202,17),Watchlist!N:N,0)),0) | J23: =IFERROR(INDEX(Watchlist!Y:Y,MATCH(LARGE(Watchlist!N5:N202,17),Watchlist!N:N,0)),0) | K23: =IFERROR(INDEX(Watchlist!Z:Z,MATCH(LARGE(Watchlist!N5:N202,17),Watchlist!N:N,0)),"")
B24: =IFERROR(INDEX(Watchlist!A:A,MATCH(LARGE(Watchlist!N5:N202,18),Watchlist!N:N,0)),"") | C24: =IFERROR(INDEX(Watchlist!D:D,MATCH(LARGE(Watchlist!N5:N202,18),Watchlist!N:N,0)),"") | D24: =IFERROR(INDEX(Watchlist!E:E,MATCH(LARGE(Watchlist!N5:N202,18),Watchlist!N:N,0)),"") | E24: =IFERROR(INDEX(Watchlist!H:H,MATCH(LARGE(Watchlist!N5:N202,18),Watchlist!N:N,0)),0) | F24: =IFERROR(INDEX(Watchlist!G:G,MATCH(LARGE(Watchlist!N5:N202,18),Watchlist!N:N,0)),"") | G24: =IFERROR(INDEX(Watchlist!M:M,MATCH(LARGE(Watchlist!N5:N202,18),Watchlist!N:N,0)),0) | H24: =IFERROR(LARGE(Watchlist!N5:N202,18),0) | I24: =IFERROR(INDEX(Watchlist!O:O,MATCH(LARGE(Watchlist!N5:N202,18),Watchlist!N:N,0)),0) | J24: =IFERROR(INDEX(Watchlist!Y:Y,MATCH(LARGE(Watchlist!N5:N202,18),Watchlist!N:N,0)),0) | K24: =IFERROR(INDEX(Watchlist!Z:Z,MATCH(LARGE(Watchlist!N5:N202,18),Watchlist!N:N,0)),"")
B25: =IFERROR(INDEX(Watchlist!A:A,MATCH(LARGE(Watchlist!N5:N202,19),Watchlist!N:N,0)),"") | C25: =IFERROR(INDEX(Watchlist!D:D,MATCH(LARGE(Watchlist!N5:N202,19),Watchlist!N:N,0)),"") | D25: =IFERROR(INDEX(Watchlist!E:E,MATCH(LARGE(Watchlist!N5:N202,19),Watchlist!N:N,0)),"") | E25: =IFERROR(INDEX(Watchlist!H:H,MATCH(LARGE(Watchlist!N5:N202,19),Watchlist!N:N,0)),0) | F25: =IFERROR(INDEX(Watchlist!G:G,MATCH(LARGE(Watchlist!N5:N202,19),Watchlist!N:N,0)),"") | G25: =IFERROR(INDEX(Watchlist!M:M,MATCH(LARGE(Watchlist!N5:N202,19),Watchlist!N:N,0)),0) | H25: =IFERROR(LARGE(Watchlist!N5:N202,19),0) | I25: =IFERROR(INDEX(Watchlist!O:O,MATCH(LARGE(Watchlist!N5:N202,19),Watchlist!N:N,0)),0) | J25: =IFERROR(INDEX(Watchlist!Y:Y,MATCH(LARGE(Watchlist!N5:N202,19),Watchlist!N:N,0)),0) | K25: =IFERROR(INDEX(Watchlist!Z:Z,MATCH(LARGE(Watchlist!N5:N202,19),Watchlist!N:N,0)),"")
B26: =IFERROR(INDEX(Watchlist!A:A,MATCH(LARGE(Watchlist!N5:N202,20),Watchlist!N:N,0)),"") | C26: =IFERROR(INDEX(Watchlist!D:D,MATCH(LARGE(Watchlist!N5:N202,20),Watchlist!N:N,0)),"") | D26: =IFERROR(INDEX(Watchlist!E:E,MATCH(LARGE(Watchlist!N5:N202,20),Watchlist!N:N,0)),"") | E26: =IFERROR(INDEX(Watchlist!H:H,MATCH(LARGE(Watchlist!N5:N202,20),Watchlist!N:N,0)),0) | F26: =IFERROR(INDEX(Watchlist!G:G,MATCH(LARGE(Watchlist!N5:N202,20),Watchlist!N:N,0)),"") | G26: =IFERROR(INDEX(Watchlist!M:M,MATCH(LARGE(Watchlist!N5:N202,20),Watchlist!N:N,0)),0) | H26: =IFERROR(LARGE(Watchlist!N5:N202,20),0) | I26: =IFERROR(INDEX(Watchlist!O:O,MATCH(LARGE(Watchlist!N5:N202,20),Watchlist!N:N,0)),0) | J26: =IFERROR(INDEX(Watchlist!Y:Y,MATCH(LARGE(Watchlist!N5:N202,20),Watchlist!N:N,0)),0) | K26: =IFERROR(INDEX(Watchlist!Z:Z,MATCH(LARGE(Watchlist!N5:N202,20),Watchlist!N:N,0)),"")
B28: OVERSOLD / TURNAROUND CANDIDATES (Bottom 10 by 30D %)
B29: CardID | C29: Card Name | D29: Set | E29: Current Price | F29: Variant | G29: 7D % | H29: 30D % | I29: 90D % | J29: Score | K29: Signal
B30: =IFERROR(INDEX(Watchlist!A:A,MATCH(SMALL(Watchlist!N5:N202,1),Watchlist!N:N,0)),"") | C30: =IFERROR(INDEX(Watchlist!D:D,MATCH(SMALL(Watchlist!N5:N202,1),Watchlist!N:N,0)),"") | D30: =IFERROR(INDEX(Watchlist!E:E,MATCH(SMALL(Watchlist!N5:N202,1),Watchlist!N:N,0)),"") | E30: =IFERROR(INDEX(Watchlist!H:H,MATCH(SMALL(Watchlist!N5:N202,1),Watchlist!N:N,0)),0) | F30: =IFERROR(INDEX(Watchlist!G:G,MATCH(SMALL(Watchlist!N5:N202,1),Watchlist!N:N,0)),"") | G30: =IFERROR(INDEX(Watchlist!M:M,MATCH(SMALL(Watchlist!N5:N202,1),Watchlist!N:N,0)),0) | H30: =IFERROR(SMALL(Watchlist!N5:N202,1),0) | I30: =IFERROR(INDEX(Watchlist!O:O,MATCH(SMALL(Watchlist!N5:N202,1),Watchlist!N:N,0)),0) | J30: =IFERROR(INDEX(Watchlist!Y:Y,MATCH(SMALL(Watchlist!N5:N202,1),Watchlist!N:N,0)),0) | K30: =IFERROR(INDEX(Watchlist!Z:Z,MATCH(SMALL(Watchlist!N5:N202,1),Watchlist!N:N,0)),"")
B31: =IFERROR(INDEX(Watchlist!A:A,MATCH(SMALL(Watchlist!N5:N202,2),Watchlist!N:N,0)),"") | C31: =IFERROR(INDEX(Watchlist!D:D,MATCH(SMALL(Watchlist!N5:N202,2),Watchlist!N:N,0)),"") | D31: =IFERROR(INDEX(Watchlist!E:E,MATCH(SMALL(Watchlist!N5:N202,2),Watchlist!N:N,0)),"") | E31: =IFERROR(INDEX(Watchlist!H:H,MATCH(SMALL(Watchlist!N5:N202,2),Watchlist!N:N,0)),0) | F31: =IFERROR(INDEX(Watchlist!G:G,MATCH(SMALL(Watchlist!N5:N202,2),Watchlist!N:N,0)),"") | G31: =IFERROR(INDEX(Watchlist!M:M,MATCH(SMALL(Watchlist!N5:N202,2),Watchlist!N:N,0)),0) | H31: =IFERROR(SMALL(Watchlist!N5:N202,2),0) | I31: =IFERROR(INDEX(Watchlist!O:O,MATCH(SMALL(Watchlist!N5:N202,2),Watchlist!N:N,0)),0) | J31: =IFERROR(INDEX(Watchlist!Y:Y,MATCH(SMALL(Watchlist!N5:N202,2),Watchlist!N:N,0)),0) | K31: =IFERROR(INDEX(Watchlist!Z:Z,MATCH(SMALL(Watchlist!N5:N202,2),Watchlist!N:N,0)),"")
B32: =IFERROR(INDEX(Watchlist!A:A,MATCH(SMALL(Watchlist!N5:N202,3),Watchlist!N:N,0)),"") | C32: =IFERROR(INDEX(Watchlist!D:D,MATCH(SMALL(Watchlist!N5:N202,3),Watchlist!N:N,0)),"") | D32: =IFERROR(INDEX(Watchlist!E:E,MATCH(SMALL(Watchlist!N5:N202,3),Watchlist!N:N,0)),"") | E32: =IFERROR(INDEX(Watchlist!H:H,MATCH(SMALL(Watchlist!N5:N202,3),Watchlist!N:N,0)),0) | F32: =IFERROR(INDEX(Watchlist!G:G,MATCH(SMALL(Watchlist!N5:N202,3),Watchlist!N:N,0)),"") | G32: =IFERROR(INDEX(Watchlist!M:M,MATCH(SMALL(Watchlist!N5:N202,3),Watchlist!N:N,0)),0) | H32: =IFERROR(SMALL(Watchlist!N5:N202,3),0) | I32: =IFERROR(INDEX(Watchlist!O:O,MATCH(SMALL(Watchlist!N5:N202,3),Watchlist!N:N,0)),0) | J32: =IFERROR(INDEX(Watchlist!Y:Y,MATCH(SMALL(Watchlist!N5:N202,3),Watchlist!N:N,0)),0) | K32: =IFERROR(INDEX(Watchlist!Z:Z,MATCH(SMALL(Watchlist!N5:N202,3),Watchlist!N:N,0)),"")
B33: =IFERROR(INDEX(Watchlist!A:A,MATCH(SMALL(Watchlist!N5:N202,4),Watchlist!N:N,0)),"") | C33: =IFERROR(INDEX(Watchlist!D:D,MATCH(SMALL(Watchlist!N5:N202,4),Watchlist!N:N,0)),"") | D33: =IFERROR(INDEX(Watchlist!E:E,MATCH(SMALL(Watchlist!N5:N202,4),Watchlist!N:N,0)),"") | E33: =IFERROR(INDEX(Watchlist!H:H,MATCH(SMALL(Watchlist!N5:N202,4),Watchlist!N:N,0)),0) | F33: =IFERROR(INDEX(Watchlist!G:G,MATCH(SMALL(Watchlist!N5:N202,4),Watchlist!N:N,0)),"") | G33: =IFERROR(INDEX(Watchlist!M:M,MATCH(SMALL(Watchlist!N5:N202,4),Watchlist!N:N,0)),0) | H33: =IFERROR(SMALL(Watchlist!N5:N202,4),0) | I33: =IFERROR(INDEX(Watchlist!O:O,MATCH(SMALL(Watchlist!N5:N202,4),Watchlist!N:N,0)),0) | J33: =IFERROR(INDEX(Watchlist!Y:Y,MATCH(SMALL(Watchlist!N5:N202,4),Watchlist!N:N,0)),0) | K33: =IFERROR(INDEX(Watchlist!Z:Z,MATCH(SMALL(Watchlist!N5:N202,4),Watchlist!N:N,0)),"")
B34: =IFERROR(INDEX(Watchlist!A:A,MATCH(SMALL(Watchlist!N5:N202,5),Watchlist!N:N,0)),"") | C34: =IFERROR(INDEX(Watchlist!D:D,MATCH(SMALL(Watchlist!N5:N202,5),Watchlist!N:N,0)),"") | D34: =IFERROR(INDEX(Watchlist!E:E,MATCH(SMALL(Watchlist!N5:N202,5),Watchlist!N:N,0)),"") | E34: =IFERROR(INDEX(Watchlist!H:H,MATCH(SMALL(Watchlist!N5:N202,5),Watchlist!N:N,0)),0) | F34: =IFERROR(INDEX(Watchlist!G:G,MATCH(SMALL(Watchlist!N5:N202,5),Watchlist!N:N,0)),"") | G34: =IFERROR(INDEX(Watchlist!M:M,MATCH(SMALL(Watchlist!N5:N202,5),Watchlist!N:N,0)),0) | H34: =IFERROR(SMALL(Watchlist!N5:N202,5),0) | I34: =IFERROR(INDEX(Watchlist!O:O,MATCH(SMALL(Watchlist!N5:N202,5),Watchlist!N:N,0)),0) | J34: =IFERROR(INDEX(Watchlist!Y:Y,MATCH(SMALL(Watchlist!N5:N202,5),Watchlist!N:N,0)),0) | K34: =IFERROR(INDEX(Watchlist!Z:Z,MATCH(SMALL(Watchlist!N5:N202,5),Watchlist!N:N,0)),"")
B35: =IFERROR(INDEX(Watchlist!A:A,MATCH(SMALL(Watchlist!N5:N202,6),Watchlist!N:N,0)),"") | C35: =IFERROR(INDEX(Watchlist!D:D,MATCH(SMALL(Watchlist!N5:N202,6),Watchlist!N:N,0)),"") | D35: =IFERROR(INDEX(Watchlist!E:E,MATCH(SMALL(Watchlist!N5:N202,6),Watchlist!N:N,0)),"") | E35: =IFERROR(INDEX(Watchlist!H:H,MATCH(SMALL(Watchlist!N5:N202,6),Watchlist!N:N,0)),0) | F35: =IFERROR(INDEX(Watchlist!G:G,MATCH(SMALL(Watchlist!N5:N202,6),Watchlist!N:N,0)),"") | G35: =IFERROR(INDEX(Watchlist!M:M,MATCH(SMALL(Watchlist!N5:N202,6),Watchlist!N:N,0)),0) | H35: =IFERROR(SMALL(Watchlist!N5:N202,6),0) | I35: =IFERROR(INDEX(Watchlist!O:O,MATCH(SMALL(Watchlist!N5:N202,6),Watchlist!N:N,0)),0) | J35: =IFERROR(INDEX(Watchlist!Y:Y,MATCH(SMALL(Watchlist!N5:N202,6),Watchlist!N:N,0)),0) | K35: =IFERROR(INDEX(Watchlist!Z:Z,MATCH(SMALL(Watchlist!N5:N202,6),Watchlist!N:N,0)),"")
B36: =IFERROR(INDEX(Watchlist!A:A,MATCH(SMALL(Watchlist!N5:N202,7),Watchlist!N:N,0)),"") | C36: =IFERROR(INDEX(Watchlist!D:D,MATCH(SMALL(Watchlist!N5:N202,7),Watchlist!N:N,0)),"") | D36: =IFERROR(INDEX(Watchlist!E:E,MATCH(SMALL(Watchlist!N5:N202,7),Watchlist!N:N,0)),"") | E36: =IFERROR(INDEX(Watchlist!H:H,MATCH(SMALL(Watchlist!N5:N202,7),Watchlist!N:N,0)),0) | F36: =IFERROR(INDEX(Watchlist!G:G,MATCH(SMALL(Watchlist!N5:N202,7),Watchlist!N:N,0)),"") | G36: =IFERROR(INDEX(Watchlist!M:M,MATCH(SMALL(Watchlist!N5:N202,7),Watchlist!N:N,0)),0) | H36: =IFERROR(SMALL(Watchlist!N5:N202,7),0) | I36: =IFERROR(INDEX(Watchlist!O:O,MATCH(SMALL(Watchlist!N5:N202,7),Watchlist!N:N,0)),0) | J36: =IFERROR(INDEX(Watchlist!Y:Y,MATCH(SMALL(Watchlist!N5:N202,7),Watchlist!N:N,0)),0) | K36: =IFERROR(INDEX(Watchlist!Z:Z,MATCH(SMALL(Watchlist!N5:N202,7),Watchlist!N:N,0)),"")
B37: =IFERROR(INDEX(Watchlist!A:A,MATCH(SMALL(Watchlist!N5:N202,8),Watchlist!N:N,0)),"") | C37: =IFERROR(INDEX(Watchlist!D:D,MATCH(SMALL(Watchlist!N5:N202,8),Watchlist!N:N,0)),"") | D37: =IFERROR(INDEX(Watchlist!E:E,MATCH(SMALL(Watchlist!N5:N202,8),Watchlist!N:N,0)),"") | E37: =IFERROR(INDEX(Watchlist!H:H,MATCH(SMALL(Watchlist!N5:N202,8),Watchlist!N:N,0)),0) | F37: =IFERROR(INDEX(Watchlist!G:G,MATCH(SMALL(Watchlist!N5:N202,8),Watchlist!N:N,0)),"") | G37: =IFERROR(INDEX(Watchlist!M:M,MATCH(SMALL(Watchlist!N5:N202,8),Watchlist!N:N,0)),0) | H37: =IFERROR(SMALL(Watchlist!N5:N202,8),0) | I37: =IFERROR(INDEX(Watchlist!O:O,MATCH(SMALL(Watchlist!N5:N202,8),Watchlist!N:N,0)),0) | J37: =IFERROR(INDEX(Watchlist!Y:Y,MATCH(SMALL(Watchlist!N5:N202,8),Watchlist!N:N,0)),0) | K37: =IFERROR(INDEX(Watchlist!Z:Z,MATCH(SMALL(Watchlist!N5:N202,8),Watchlist!N:N,0)),"")
B38: =IFERROR(INDEX(Watchlist!A:A,MATCH(SMALL(Watchlist!N5:N202,9),Watchlist!N:N,0)),"") | C38: =IFERROR(INDEX(Watchlist!D:D,MATCH(SMALL(Watchlist!N5:N202,9),Watchlist!N:N,0)),"") | D38: =IFERROR(INDEX(Watchlist!E:E,MATCH(SMALL(Watchlist!N5:N202,9),Watchlist!N:N,0)),"") | E38: =IFERROR(INDEX(Watchlist!H:H,MATCH(SMALL(Watchlist!N5:N202,9),Watchlist!N:N,0)),0) | F38: =IFERROR(INDEX(Watchlist!G:G,MATCH(SMALL(Watchlist!N5:N202,9),Watchlist!N:N,0)),"") | G38: =IFERROR(INDEX(Watchlist!M:M,MATCH(SMALL(Watchlist!N5:N202,9),Watchlist!N:N,0)),0) | H38: =IFERROR(SMALL(Watchlist!N5:N202,9),0) | I38: =IFERROR(INDEX(Watchlist!O:O,MATCH(SMALL(Watchlist!N5:N202,9),Watchlist!N:N,0)),0) | J38: =IFERROR(INDEX(Watchlist!Y:Y,MATCH(SMALL(Watchlist!N5:N202,9),Watchlist!N:N,0)),0) | K38: =IFERROR(INDEX(Watchlist!Z:Z,MATCH(SMALL(Watchlist!N5:N202,9),Watchlist!N:N,0)),"")
B39: =IFERROR(INDEX(Watchlist!A:A,MATCH(SMALL(Watchlist!N5:N202,10),Watchlist!N:N,0)),"") | C39: =IFERROR(INDEX(Watchlist!D:D,MATCH(SMALL(Watchlist!N5:N202,10),Watchlist!N:N,0)),"") | D39: =IFERROR(INDEX(Watchlist!E:E,MATCH(SMALL(Watchlist!N5:N202,10),Watchlist!N:N,0)),"") | E39: =IFERROR(INDEX(Watchlist!H:H,MATCH(SMALL(Watchlist!N5:N202,10),Watchlist!N:N,0)),0) | F39: =IFERROR(INDEX(Watchlist!G:G,MATCH(SMALL(Watchlist!N5:N202,10),Watchlist!N:N,0)),"") | G39: =IFERROR(INDEX(Watchlist!M:M,MATCH(SMALL(Watchlist!N5:N202,10),Watchlist!N:N,0)),0) | H39: =IFERROR(SMALL(Watchlist!N5:N202,10),0) | I39: =IFERROR(INDEX(Watchlist!O:O,MATCH(SMALL(Watchlist!N5:N202,10),Watchlist!N:N,0)),0) | J39: =IFERROR(INDEX(Watchlist!Y:Y,MATCH(SMALL(Watchlist!N5:N202,10),Watchlist!N:N,0)),0) | K39: =IFERROR(INDEX(Watchlist!Z:Z,MATCH(SMALL(Watchlist!N5:N202,10),Watchlist!N:N,0)),"")

Sheet Watchlist
A1: WATCHLIST — 674 Cards with Quant Scoring (May 12, 2026)
A2: Composite Score = 0.4×Momentum + 0.25×Value + 0.2×Scarcity + 0.15×Liquidity. Signals refresh automatically when prices update.
A4: CardID | B4: Category | C4: Tier | D4: Card Name | E4: Set | F4: Card # | G4: Variant / Grade | H4: Current Price | I4: Last Updated | J4: Price 7D Ago | K4: Price 30D Ago | L4: Price 90D Ago | M4: 7D % | N4: 30D % | O4: 90D % | P4: Target Buy | Q4: Target Sell | R4: Horizon | S4: Conf | T4: Pop PSA10 | U4: Momentum | V4: Value | W4: Scarcity | X4: Liquidity | Y4: Composite | Z4: Signal | AA4: Source URL | AB4: Notes
A5: V001 | B5: Vintage Graded Singles | C5: T1 | D5: Charizard | E5: Base Set 1st Edition Shadowless | F5: 4/102 | G5: PSA 9 | H5: 32000 | I5: 46153 | J5: 32360.48 | K5: 31986.85 | L5: 30646.16 | M5: =IFERROR((H5-J5)/J5,0) | N5: =IFERROR((H5-K5)/K5,0) | O5: =IFERROR((H5-L5)/L5,0) | P5: 25000 | Q5: 45000 | R5: 5-10yr | S5: 5 | T5: 121 | U5: =MAX(0,MIN(100,50+((M5*0.6)+(N5*0.4))*200)) | V5: =MAX(20,MIN(100,50+(P5-H5)/P5*100)) | W5: =IFERROR(MAX(0,MIN(100,100-LOG10(T5)*16)),60) | X5: =IF(C5="T2",85,IF(C5="T4",70,IF(C5="T1",65,IF(C5="T3",55,45)))) | Y5: =U5*0.55+W5*0.20+V5*0.15+X5*0.10+ROW()/1000000 | Z5: =IF(Y5>=75,"STRONG BUY",IF(Y5>=60,"BUY",IF(Y5>=40,"HOLD",IF(Y5>=25,"TRIM","SELL")))) | AA5: https://www.pricecharting.com/game/pokemon-base-set/charizard-1st-edition-4 | AB5: Crown jewel. PSA 10 is $200K+. Pop ~121 PSA 9 = institutional grade.
A6: V002 | B6: Vintage Graded Singles | C6: T1 | D6: Charizard | E6: Base Set 1st Edition Shadowless | F6: 4/102 | G6: PSA 8 | H6: 9500 | I6: 46153 | J6: 9551.49 | K6: 9278.6 | L6: 8882.26 | M6: =IFERROR((H6-J6)/J6,0) | N6: =IFERROR((H6-K6)/K6,0) | O6: =IFERROR((H6-L6)/L6,0) | P6: 7500 | Q6: 13000 | R6: 5-10yr | S6: 5 | T6: 980 | U6: =MAX(0,MIN(100,50+((M6*0.6)+(N6*0.4))*200)) | V6: =MAX(20,MIN(100,50+(P6-H6)/P6*100)) | W6: =IFERROR(MAX(0,MIN(100,100-LOG10(T6)*16)),60) | X6: =IF(C6="T2",85,IF(C6="T4",70,IF(C6="T1",65,IF(C6="T3",55,45)))) | Y6: =U6*0.55+W6*0.20+V6*0.15+X6*0.10+ROW()/1000000 | Z6: =IF(Y6>=75,"STRONG BUY",IF(Y6>=60,"BUY",IF(Y6>=40,"HOLD",IF(Y6>=25,"TRIM","SELL")))) | AA6: https://www.pricecharting.com/game/pokemon-base-set/charizard-1st-edition-4 | AB6: PSA 8 entry-tier to 1st Ed Charizard. More liquid.
A7: V003 | B7: Vintage Graded Singles | C7: T1 | D7: Charizard | E7: Base Set Shadowless | F7: 4/102 | G7: PSA 9 | H7: 9500 | I7: 46153 | J7: 9491.39 | K7: 9142.94 | L7: 8803.62 | M7: =IFERROR((H7-J7)/J7,0) | N7: =IFERROR((H7-K7)/K7,0) | O7: =IFERROR((H7-L7)/L7,0) | P7: 7500 | Q7: 13000 | R7: 5-10yr | S7: 5 | T7: 600 | U7: =MAX(0,MIN(100,50+((M7*0.6)+(N7*0.4))*200)) | V7: =MAX(20,MIN(100,50+(P7-H7)/P7*100)) | W7: =IFERROR(MAX(0,MIN(100,100-LOG10(T7)*16)),60) | X7: =IF(C7="T2",85,IF(C7="T4",70,IF(C7="T1",65,IF(C7="T3",55,45)))) | Y7: =U7*0.55+W7*0.20+V7*0.15+X7*0.10+ROW()/1000000 | Z7: =IF(Y7>=75,"STRONG BUY",IF(Y7>=60,"BUY",IF(Y7>=40,"HOLD",IF(Y7>=25,"TRIM","SELL")))) | AA7: https://www.pricecharting.com/game/pokemon-base-set/charizard-shadowless-4 | AB7: Shadowless (no 1st Ed stamp). Affordable Charizard institutional play.
A8: V004 | B8: Vintage Graded Singles | C8: T1 | D8: Charizard | E8: Base Set Unlimited | F8: 4/102 | G8: PSA 10 | H8: 8000 | I8: 46153 | J8: 8057.48 | K8: 7499.61 | L8: 7235.96 | M8: =IFERROR((H8-J8)/J8,0) | N8: =IFERROR((H8-K8)/K8,0) | O8: =IFERROR((H8-L8)/L8,0) | P8: 6000 | Q8: 11000 | R8: 5-10yr | S8: 4 | T8: 1800 | U8: =MAX(0,MIN(100,50+((M8*0.6)+(N8*0.4))*200)) | V8: =MAX(20,MIN(100,50+(P8-H8)/P8*100)) | W8: =IFERROR(MAX(0,MIN(100,100-LOG10(T8)*16)),60) | X8: =IF(C8="T2",85,IF(C8="T4",70,IF(C8="T1",65,IF(C8="T3",55,45)))) | Y8: =U8*0.55+W8*0.20+V8*0.15+X8*0.10+ROW()/1000000 | Z8: =IF(Y8>=75,"STRONG BUY",IF(Y8>=60,"BUY",IF(Y8>=40,"HOLD",IF(Y8>=25,"TRIM","SELL")))) | AA8: https://www.pricecharting.com/game/pokemon-base-set/charizard-4 | AB8: Unlimited PSA 10 ceiling. Recent climb on Mega Charizard reintroduction.
A9: V005 | B9: Vintage Graded Singles | C9: T1 | D9: Charizard | E9: Base Set Unlimited | F9: 4/102 | G9: PSA 9 | H9: 3126 | I9: 46153 | J9: 1776.57 | K9: 1697.73 | L9: 1558.03 | M9: =IFERROR((H9-J9)/J9,0) | N9: =IFERROR((H9-K9)/K9,0) | O9: =IFERROR((H9-L9)/L9,0) | P9: 2300 | Q9: 4700 | R9: 5-10yr | S9: 4 | T9: 4500 | U9: =MAX(0,MIN(100,50+((M9*0.6)+(N9*0.4))*200)) | V9: =MAX(20,MIN(100,50+(P9-H9)/P9*100)) | W9: =IFERROR(MAX(0,MIN(100,100-LOG10(T9)*16)),60) | X9: =IF(C9="T2",85,IF(C9="T4",70,IF(C9="T1",65,IF(C9="T3",55,45)))) | Y9: =U9*0.55+W9*0.20+V9*0.15+X9*0.10+ROW()/1000000 | Z9: =IF(Y9>=75,"STRONG BUY",IF(Y9>=60,"BUY",IF(Y9>=40,"HOLD",IF(Y9>=25,"TRIM","SELL")))) | AA9: https://www.pricecharting.com/game/pokemon-base-set/charizard-4 | AB9: Most accessible holo Charizard. Rides Charizard tide.
A10: V006 | B10: Vintage Graded Singles | C10: T1 | D10: Blastoise | E10: Base Set 1st Edition Shadowless | F10: 2/102 | G10: PSA 9 | H10: 6500 | I10: 46153 | J10: 6519.85 | K10: 6394.47 | L10: 6079.81 | M10: =IFERROR((H10-J10)/J10,0) | N10: =IFERROR((H10-K10)/K10,0) | O10: =IFERROR((H10-L10)/L10,0) | P10: 5000 | Q10: 9000 | R10: 5-10yr | S10: 4 | T10: 280 | U10: =MAX(0,MIN(100,50+((M10*0.6)+(N10*0.4))*200)) | V10: =MAX(20,MIN(100,50+(P10-H10)/P10*100)) | W10: =IFERROR(MAX(0,MIN(100,100-LOG10(T10)*16)),60) | X10: =IF(C10="T2",85,IF(C10="T4",70,IF(C10="T1",65,IF(C10="T3",55,45)))) | Y10: =U10*0.55+W10*0.20+V10*0.15+X10*0.10+ROW()/1000000 | Z10: =IF(Y10>=75,"STRONG BUY",IF(Y10>=60,"BUY",IF(Y10>=40,"HOLD",IF(Y10>=25,"TRIM","SELL")))) | AA10: https://www.pricecharting.com/game/pokemon-base-set/blastoise-1st-edition-2 | AB10: Original starter holo. Less Charizard correlation = portfolio diversifier.
A11: V007 | B11: Vintage Graded Singles | C11: T1 | D11: Venusaur | E11: Base Set 1st Edition Shadowless | F11: 15/102 | G11: PSA 9 | H11: 4800 | I11: 46153 | J11: 4820.96 | K11: 4704.15 | L11: 4655.21 | M11: =IFERROR((H11-J11)/J11,0) | N11: =IFERROR((H11-K11)/K11,0) | O11: =IFERROR((H11-L11)/L11,0) | P11: 3800 | Q11: 6800 | R11: 5-10yr | S11: 4 | T11: 320 | U11: =MAX(0,MIN(100,50+((M11*0.6)+(N11*0.4))*200)) | V11: =MAX(20,MIN(100,50+(P11-H11)/P11*100)) | W11: =IFERROR(MAX(0,MIN(100,100-LOG10(T11)*16)),60) | X11: =IF(C11="T2",85,IF(C11="T4",70,IF(C11="T1",65,IF(C11="T3",55,45)))) | Y11: =U11*0.55+W11*0.20+V11*0.15+X11*0.10+ROW()/1000000 | Z11: =IF(Y11>=75,"STRONG BUY",IF(Y11>=60,"BUY",IF(Y11>=40,"HOLD",IF(Y11>=25,"TRIM","SELL")))) | AA11: https://www.pricecharting.com/game/pokemon-base-set/venusaur-1st-edition-15 | AB11: Cheapest of the 3 1st Ed starter holos. Symmetry play with V001/V006.
A12: V008 | B12: Vintage Graded Singles | C12: T1 | D12: Chansey | E12: Base Set 1st Edition | F12: 3/102 | G12: PSA 9 | H12: 1100 | I12: 46153 | J12: 1072.31 | K12: 1076.04 | L12: 980.57 | M12: =IFERROR((H12-J12)/J12,0) | N12: =IFERROR((H12-K12)/K12,0) | O12: =IFERROR((H12-L12)/L12,0) | P12: 850 | Q12: 1500 | R12: 5-10yr | S12: 3 | T12: 850 | U12: =MAX(0,MIN(100,50+((M12*0.6)+(N12*0.4))*200)) | V12: =MAX(20,MIN(100,50+(P12-H12)/P12*100)) | W12: =IFERROR(MAX(0,MIN(100,100-LOG10(T12)*16)),60) | X12: =IF(C12="T2",85,IF(C12="T4",70,IF(C12="T1",65,IF(C12="T3",55,45)))) | Y12: =U12*0.55+W12*0.20+V12*0.15+X12*0.10+ROW()/1000000 | Z12: =IF(Y12>=75,"STRONG BUY",IF(Y12>=60,"BUY",IF(Y12>=40,"HOLD",IF(Y12>=25,"TRIM","SELL")))) | AA12: https://www.pricecharting.com/game/pokemon-base-set/chansey-1st-edition-3 | AB12: Trophy run-up potential. Cheap 1st Ed PSA 9.
A13: V009 | B13: Vintage Graded Singles | C13: T1 | D13: Mewtwo | E13: Base Set 1st Edition | F13: 10/102 | G13: PSA 9 | H13: 1400 | I13: 46153 | J13: 1371.66 | K13: 1323.46 | L13: 1195 | M13: =IFERROR((H13-J13)/J13,0) | N13: =IFERROR((H13-K13)/K13,0) | O13: =IFERROR((H13-L13)/L13,0) | P13: 1100 | Q13: 2000 | R13: 5-10yr | S13: 4 | T13: 700 | U13: =MAX(0,MIN(100,50+((M13*0.6)+(N13*0.4))*200)) | V13: =MAX(20,MIN(100,50+(P13-H13)/P13*100)) | W13: =IFERROR(MAX(0,MIN(100,100-LOG10(T13)*16)),60) | X13: =IF(C13="T2",85,IF(C13="T4",70,IF(C13="T1",65,IF(C13="T3",55,45)))) | Y13: =U13*0.55+W13*0.20+V13*0.15+X13*0.10+ROW()/1000000 | Z13: =IF(Y13>=75,"STRONG BUY",IF(Y13>=60,"BUY",IF(Y13>=40,"HOLD",IF(Y13>=25,"TRIM","SELL")))) | AA13: https://www.pricecharting.com/game/pokemon-base-set/mewtwo-1st-edition-10 | AB13: Mewtwo brand strength; Genesis/Detective Pikachu/Mega exposure.
A14: V010 | B14: Vintage Graded Singles | C14: T1 | D14: Alakazam | E14: Base Set 1st Edition | F14: 1/102 | G14: PSA 9 | H14: 950 | I14: 46153 | J14: 961.58 | K14: 920.9 | L14: 890.98 | M14: =IFERROR((H14-J14)/J14,0) | N14: =IFERROR((H14-K14)/K14,0) | O14: =IFERROR((H14-L14)/L14,0) | P14: 750 | Q14: 1300 | R14: 5-10yr | S14: 3 | T14: 600 | U14: =MAX(0,MIN(100,50+((M14*0.6)+(N14*0.4))*200)) | V14: =MAX(20,MIN(100,50+(P14-H14)/P14*100)) | W14: =IFERROR(MAX(0,MIN(100,100-LOG10(T14)*16)),60) | X14: =IF(C14="T2",85,IF(C14="T4",70,IF(C14="T1",65,IF(C14="T3",55,45)))) | Y14: =U14*0.55+W14*0.20+V14*0.15+X14*0.10+ROW()/1000000 | Z14: =IF(Y14>=75,"STRONG BUY",IF(Y14>=60,"BUY",IF(Y14>=40,"HOLD",IF(Y14>=25,"TRIM","SELL")))) | AA14: https://www.pricecharting.com/game/pokemon-base-set/alakazam-1st-edition-1 | AB14: Card #1/102 collector premium. Cheap entry.
A15: V011 | B15: Vintage Graded Singles | C15: T1 | D15: Ninetales | E15: Base Set 1st Edition | F15: 12/102 | G15: PSA 9 | H15: 1100 | I15: 46153 | J15: 1083.78 | K15: 1035.94 | L15: 977.65 | M15: =IFERROR((H15-J15)/J15,0) | N15: =IFERROR((H15-K15)/K15,0) | O15: =IFERROR((H15-L15)/L15,0) | P15: 850 | Q15: 1500 | R15: 5-10yr | S15: 3 | T15: 500 | U15: =MAX(0,MIN(100,50+((M15*0.6)+(N15*0.4))*200)) | V15: =MAX(20,MIN(100,50+(P15-H15)/P15*100)) | W15: =IFERROR(MAX(0,MIN(100,100-LOG10(T15)*16)),60) | X15: =IF(C15="T2",85,IF(C15="T4",70,IF(C15="T1",65,IF(C15="T3",55,45)))) | Y15: =U15*0.55+W15*0.20+V15*0.15+X15*0.10+ROW()/1000000 | Z15: =IF(Y15>=75,"STRONG BUY",IF(Y15>=60,"BUY",IF(Y15>=40,"HOLD",IF(Y15>=25,"TRIM","SELL")))) | AA15: https://www.pricecharting.com/game/pokemon-base-set/ninetales-1st-edition-12 | AB15: Underrated 1st Ed holo. Strong fox IP.
A16: V012 | B16: Vintage Graded Singles | C16: T1 | D16: Zapdos | E16: Base Set 1st Edition | F16: 16/102 | G16: PSA 9 | H16: 1050 | I16: 46153 | J16: 1037.08 | K16: 992.39 | L16: 961.64 | M16: =IFERROR((H16-J16)/J16,0) | N16: =IFERROR((H16-K16)/K16,0) | O16: =IFERROR((H16-L16)/L16,0) | P16: 800 | Q16: 1400 | R16: 5-10yr | S16: 3 | T16: 540 | U16: =MAX(0,MIN(100,50+((M16*0.6)+(N16*0.4))*200)) | V16: =MAX(20,MIN(100,50+(P16-H16)/P16*100)) | W16: =IFERROR(MAX(0,MIN(100,100-LOG10(T16)*16)),60) | X16: =IF(C16="T2",85,IF(C16="T4",70,IF(C16="T1",65,IF(C16="T3",55,45)))) | Y16: =U16*0.55+W16*0.20+V16*0.15+X16*0.10+ROW()/1000000 | Z16: =IF(Y16>=75,"STRONG BUY",IF(Y16>=60,"BUY",IF(Y16>=40,"HOLD",IF(Y16>=25,"TRIM","SELL")))) | AA16: https://www.pricecharting.com/game/pokemon-base-set/zapdos-1st-edition-16 | AB16: Legendary bird 1st Ed. Cheaper than Articuno/Moltres.
... A40: M001 | B40: Modern Chase PSA 10 | C40: T2 | D40: Umbreon VMAX (Moonbreon) | E40: Evolving Skies | F40: 215/203 | G40: PSA 10 | H40: 4480 | I40: 46153 | J40: 1551.29 | K40: 1650.35 | L40: 1882.05 | M40: =IFERROR((H40-J40)/J40,0) | N40: =IFERROR((H40-K40)/K40,0) | O40: =IFERROR((H40-L40)/L40,0) | P40: 3500 | Q40: 6000 | R40: 5-10yr | S40: 5 | T40: 3500 | U40: =MAX(0,MIN(100,50+((M40*0.6)+(N40*0.4))*200)) | V40: =MAX(20,MIN(100,50+(P40-H40)/P40*100)) | W40: =IFERROR(MAX(0,MIN(100,100-LOG10(T40)*16)),60) | X40: =IF(C40="T2",85,IF(C40="T4",70,IF(C40="T1",65,IF(C40="T3",55,45)))) | Y40: =U40*0.55+W40*0.20+V40*0.15+X40*0.10+ROW()/1000000 | Z40: =IF(Y40>=75,"STRONG BUY",IF(Y40>=60,"BUY",IF(Y40>=40,"HOLD",IF(Y40>=25,"TRIM","SELL")))) | AA40: https://www.tcgplayer.com/product/246723 | AB40: Most-traded modern card. Retraced from $2,300 Oct'25 peak. Re-entry zone.
A41: M002 | B41: Modern Chase PSA 10 | C41: T4 | D41: Umbreon VMAX (Moonbreon) | E41: Evolving Skies | F41: 215/203 | G41: Raw NM | H41: 2100 | I41: 46153 | J41: 559.13 | K41: 629.84 | L41: 775.75 | M41: =IFERROR((H41-J41)/J41,0) | N41: =IFERROR((H41-K41)/K41,0) | O41: =IFERROR((H41-L41)/L41,0) | P41: 1600 | Q41: 3200 | R41: 1-3yr | S41: 4 | U41: =MAX(0,MIN(100,50+((M41*0.6)+(N41*0.4))*200)) | V41: =MAX(20,MIN(100,50+(P41-H41)/P41*100)) | W41: =IFERROR(MAX(0,MIN(100,100-LOG10(T41)*16)),60) | X41: =IF(C41="T2",85,IF(C41="T4",70,IF(C41="T1",65,IF(C41="T3",55,45)))) | Y41: =U41*0.55+W41*0.20+V41*0.15+X41*0.10+ROW()/1000000 | Z41: =IF(Y41>=75,"STRONG BUY",IF(Y41>=60,"BUY",IF(Y41>=40,"HOLD",IF(Y41>=25,"TRIM","SELL")))) | AA41: https://www.tcgplayer.com/product/246723 | AB41: Raw grading play. PSA 10 rate ~42%. Math: $575 cost vs $1,500 = +160% upside.
A42: M003 | B42: Modern Chase PSA 10 | C42: T2 | D42: Rayquaza VMAX Alt Art | E42: Evolving Skies | F42: 218/203 | G42: PSA 10 | H42: 1480 | I42: 46153 | J42: 969.21 | K42: 1009.54 | L42: 1075.11 | M42: =IFERROR((H42-J42)/J42,0) | N42: =IFERROR((H42-K42)/K42,0) | O42: =IFERROR((H42-L42)/L42,0) | P42: 1100 | Q42: 2100 | R42: 5-10yr | S42: 4 | T42: 2800 | U42: =MAX(0,MIN(100,50+((M42*0.6)+(N42*0.4))*200)) | V42: =MAX(20,MIN(100,50+(P42-H42)/P42*100)) | W42: =IFERROR(MAX(0,MIN(100,100-LOG10(T42)*16)),60) | X42: =IF(C42="T2",85,IF(C42="T4",70,IF(C42="T1",65,IF(C42="T3",55,45)))) | Y42: =U42*0.55+W42*0.20+V42*0.15+X42*0.10+ROW()/1000000 | Z42: =IF(Y42>=75,"STRONG BUY",IF(Y42>=60,"BUY",IF(Y42>=40,"HOLD",IF(Y42>=25,"TRIM","SELL")))) | AA42: https://www.tcgplayer.com/product/246726 | AB42: Second-best ES alt art. Dragon legendary tier.
A43: M004 | B43: Modern Chase PSA 10 | C43: T2 | D43: Sylveon VMAX Alt Art | E43: Evolving Skies | F43: 212/203 | G43: PSA 10 | H43: 1200 | I43: 46153 | J43: 701.67 | K43: 655.76 | L43: 592.35 | M43: =IFERROR((H43-J43)/J43,0) | N43: =IFERROR((H43-K43)/K43,0) | O43: =IFERROR((H43-L43)/L43,0) | P43: 900 | Q43: 1800 | R43: 5-10yr | S43: 4 | T43: 2400 | U43: =MAX(0,MIN(100,50+((M43*0.6)+(N43*0.4))*200)) | V43: =MAX(20,MIN(100,50+(P43-H43)/P43*100)) | W43: =IFERROR(MAX(0,MIN(100,100-LOG10(T43)*16)),60) | X43: =IF(C43="T2",85,IF(C43="T4",70,IF(C43="T1",65,IF(C43="T3",55,45)))) | Y43: =U43*0.55+W43*0.20+V43*0.15+X43*0.10+ROW()/1000000 | Z43: =IF(Y43>=75,"STRONG BUY",IF(Y43>=60,"BUY",IF(Y43>=40,"HOLD",IF(Y43>=25,"TRIM","SELL")))) | AA43: https://www.tcgplayer.com/product/246720 | AB43: Eeveelution sister to Moonbreon. Tracks at 50% discount.
A44: M005 | B44: Modern Chase PSA 10 | C44: T2 | D44: Espeon VMAX Alt Art | E44: Evolving Skies | F44: 208/203 | G44: PSA 10 | H44: 1100 | I44: 46153 | J44: 680.13 | K44: 641.61 | L44: 582.01 | M44: =IFERROR((H44-J44)/J44,0) | N44: =IFERROR((H44-K44)/K44,0) | O44: =IFERROR((H44-L44)/L44,0) | P44: 850 | Q44: 1600 | R44: 5-10yr | S44: 4 | T44: 2200 | U44: =MAX(0,MIN(100,50+((M44*0.6)+(N44*0.4))*200)) | V44: =MAX(20,MIN(100,50+(P44-H44)/P44*100)) | W44: =IFERROR(MAX(0,MIN(100,100-LOG10(T44)*16)),60) | X44: =IF(C44="T2",85,IF(C44="T4",70,IF(C44="T1",65,IF(C44="T3",55,45)))) | Y44: =U44*0.55+W44*0.20+V44*0.15+X44*0.10+ROW()/1000000 | Z44: =IF(Y44>=75,"STRONG BUY",IF(Y44>=60,"BUY",IF(Y44>=40,"HOLD",IF(Y44>=25,"TRIM","SELL")))) | AA44: https://www.tcgplayer.com/product/246716 | AB44: Sun Eeveelution. Buy on dips below $550.
